<?xml version="1.0" encoding="utf-8"?>
<robot name="right_arm">
  <link name="base_link">
    <inertial>
      <origin xyz="-0.046219 -0.034827 0.169451" rpy="0 0 0" />
      <mass value="1.477" />
      <inertia ixx="0.008577" ixy="-1.039E-06" ixz="2.278E-05" iyy="0.009215" iyz="9.518E-07" izz="0.001158" />
    </inertial>
    <visual>
      <origin xyz="0 0 0" rpy="0 0 0" />
      <geometry>
        <mesh filename="../meshes/base_link.STL" />
      </geometry>
      <material name="">
        <color rgba="0.19 0.20 0.20 1" />
      </material>
    </visual>
    <collision>
      <origin xyz="-0.05 0 0.12" rpy="0 0 0" />
      <geometry>
        <box size="0.03 0.03 0.3"/>
      </geometry>
    </collision>
    <collision>
      <origin xyz="-0.05 -0.055 0.235" rpy="1.5708 0 0" />
      <geometry>
        <cylinder radius="0.06" length="0.07" />
      </geometry>
    </collision>
  </link>
  <link name="right_shoulder_pitch_link">
    <inertial>
      <origin xyz="-0.005325 8.266E-07 0.08346" rpy="0 0 0" />
      <mass value="1.131" />
      <inertia ixx="0.001120" ixy="-1.335E-07" ixz="-6.500E-06" iyy="0.0007355" iyz="-7.122E-07" izz="0.0007427" />
    </inertial>
    <visual>
      <origin xyz="0 0 0" rpy="0 0 0" />
      <geometry>
        <mesh filename="../meshes/right_shoulder_pitch_link.STL" />
      </geometry>
      <material name="">
        <color rgba="0.65 0.62 0.59 1" />
      </material>
    </visual>
    <collision>
      <origin xyz="0 0 0.06" rpy="0 0 0" />
      <geometry>
        <cylinder radius="0.04" length="0.05" />
      </geometry>
    </collision>
    <collision>
      <origin xyz="0 0 0.13" rpy="0 1.5708 0" />
      <geometry>
        <cylinder radius="0.046" length="0.07" />
      </geometry>
    </collision>
  </link>
  <joint name="right_shoulder_pitch" type="revolute">
    <origin xyz="-0.0484 -0.0673 0.23774" rpy="1.5708 -1.0471975511965976 0" />
    <parent link="base_link" />
    <child link="right_shoulder_pitch_link" />
    <axis xyz="0 0 1" />
    <limit lower="-1.71" upper="1.71" effort="25" velocity="4.19" />
  </joint>
  <link name="right_shoulder_roll_link">
    <inertial>
      <origin xyz="8.837E-06 -0.07657 0.007176" rpy="0 0 0" />
      <mass value="0.850" />
      <inertia ixx="0.0007163" ixy="1.694E-08" ixz="-5.619E-07" iyy="0.0008543" iyz="5.436E-06" izz="0.0007770" />
    </inertial>
    <visual>
      <origin xyz="0 0 0" rpy="0 0 0" />
      <geometry>
        <mesh filename="../meshes/right_shoulder_roll_link.STL" />
      </geometry>
      <material name="">
        <color rgba="0.19 0.20 0.20 1" />
      </material>
    </visual>
    <collision>
      <origin xyz="0 -0.1 0" rpy="1.5708 0 0" />
      <geometry>
        <cylinder radius="0.046" length="0.07" />
      </geometry>
    </collision>
  </link>
  <joint name="right_shoulder_roll" type="revolute">
    <origin xyz="-0.00505 0 0.1255" rpy="-1.5708 0 -1.5708" />
    <parent link="right_shoulder_pitch_link" />
    <child link="right_shoulder_roll_link" />
    <axis xyz="0 0 1" />
    <limit lower="-1.92" upper="1.92" effort="25" velocity="4.19" />
  </joint>
  <link name="right_shoulder_yaw_link">
    <inertial>
      <origin xyz="2.847E-05 0.003227 0.102424" rpy="0 0 0" />
      <mass value="1.202" />
      <inertia ixx="0.00102629" ixy="1.422E-07" ixz="1.234E-08" iyy="0.0012418" iyz="-5.632E-06" izz="0.00054793" />
    </inertial>
    <visual>
      <origin xyz="0 0 0" rpy="0 0 0" />
      <geometry>
        <mesh filename="../meshes/right_shoulder_yaw_link.STL" />
      </geometry>
      <material name="">
        <color rgba="0.79 0.82 0.93 1" />
      </material>
    </visual>
    <collision>
      <origin xyz="0 0 0.14" rpy="0 0 0" />
      <geometry>
        <cylinder radius="0.035" length="0.15" />
      </geometry>
    </collision>
  </link>
  <joint name="right_shoulder_yaw" type="revolute">
    <origin xyz="0 -0.0909 0.00505" rpy="1.5708 -1.5708 0" />
    <parent link="right_shoulder_roll_link" />
    <child link="right_shoulder_yaw_link" />
    <axis xyz="0 0 1" />
    <limit lower="-1.71" upper="1.71" effort="18" velocity="7.33" />
  </joint>
  <link name="right_forearm">
    <inertial>
      <origin xyz="0.105563 0.0079076 0.0018363" rpy="0 0 0" />
      <mass value="0.916" />
      <inertia ixx="0.000399696" ixy="-0.00011456" ixz="1.856E-06" iyy="0.002822460" iyz="-1.519E-07" izz="0.00297392" />
    </inertial>
    <visual>
      <origin xyz="0 0 0" rpy="0 0 0" />
      <geometry>
        <mesh filename="../meshes/right_forearm.STL" />
      </geometry>
      <material name="">
        <color rgba="0.90 0.92 0.93 1" />
      </material>
    </visual>
    <collision>
      <origin xyz="0.12 0 -0.02" rpy="0 1.5708 0" />
      <geometry>
        <box size="0.028 0.03 0.125" />
      </geometry>
    </collision>
  </link>
  <joint name="right_elbow" type="revolute">
    <origin xyz="0 0.00155 0.182" rpy="1.5708 -1.5708 0" />
    <parent link="right_shoulder_yaw_link" />
    <child link="right_forearm" />
    <axis xyz="0 0 1" />
    <limit lower="-2.27" upper="2.27" effort="18" velocity="7.33" />
  </joint>
  <link name="right_wrist_motor_in_link">
    <inertial>
      <origin xyz="0.00048650 0.01489087 0.0186098" rpy="0 0 0" />
      <mass value="0.0314" />
      <inertia ixx="6.479E-06" ixy="-1.603E-07" ixz="-1.488E-09" iyy="1.578E-06" iyz="-4.553E-08" izz="7.359E-06" />
    </inertial>
    <visual>
      <origin xyz="0 0 0" rpy="0 0 0" />
      <geometry>
        <mesh filename="../meshes/right_wrist_motor_in_link.STL" />
      </geometry>
      <material name="">
        <color rgba="0.90 0.92 0.93 1" />
      </material>
    </visual>
    <collision>
      <origin xyz="0 0.02 0.023" rpy="0 0 0" />
      <geometry>
        <box size="0.02 0.06 0.005" />
      </geometry>
    </collision>
  </link>
  <joint name="right_wrist_motor_in" type="revolute">
    <origin xyz="0.13 0.013 0.0286" rpy="3.1416 0 0" />
    <parent link="right_forearm" />
    <child link="right_wrist_motor_in_link" />
    <axis xyz="0 0 1" />
    <limit lower="-0.52" upper="0.52" effort="3.5" velocity="19.9" />
  </joint>
  <link name="right_wrist_bead_a_in_link">
    <inertial>
      <origin xyz="0. 0. 0." rpy="0 0 0" />
      <mass value="0.001" />
    </inertial>
    <visual>
      <origin xyz="0 0 0" rpy="0 0 0" />
      <geometry>
        <sphere radius="0.0045" />
      </geometry>
    </visual>
  </link>
  <joint name="right_wrist_bead_a_in" type="prismatic">
    <origin xyz="0.0016327 0.049973 0.012" rpy="3.1416 0 0" />
    <parent link="right_wrist_motor_in_link" />
    <child link="right_wrist_bead_a_in_link" />
    <axis xyz="0 0 1" />
    <limit lower="-0.001" upper="0.001" effort="0" velocity="10" />
  </joint>
  <link name="right_wrist_rod_in_link">
    <inertial>
      <origin xyz="0.05164914 0.00292395 0.01251506" rpy="0 0 0" />
      <mass value="0.00696" />
      <inertia ixx="8.432E-08" ixy="-2.464E-07" ixz="-7.012E-08" iyy="1.766E-06" iyz="-9.519E-09" izz="1.809E-06" />
    </inertial>
    <visual>
      <origin xyz="0 0 0" rpy="0 0 0" />
      <geometry>
        <mesh filename="../meshes/right_wrist_rod_in_link.STL" />
      </geometry>
      <material name="">
        <color rgba="0.689 0.69 0.69 1" />
      </material>
    </visual>
    <collision>
      <origin xyz="0.045 0 0.012" rpy="0 1.5708 0" />
      <geometry>
        <cylinder radius="0.004" length="0.1" />
      </geometry>
    </collision>
  </link>
  <joint name="right_wrist_rod_in" type="revolute">
    <origin xyz="0. 0. -0.01" rpy="0 0 0" />
    <parent link="right_wrist_bead_a_in_link" />
    <child link="right_wrist_rod_in_link" />
    <axis xyz="0 0 1" />
    <limit lower="0" upper="0" effort="0" velocity="0" />
  </joint>
  <link name="right_wrist_bead_b_in_link">
    <inertial>
      <origin xyz="0. 0. 0." rpy="0 0 0" />
      <mass value="0.001" />
    </inertial>
    <visual>
      <origin xyz="0 0 0.0" rpy="0 0 0" />
      <geometry>
        <sphere radius="0.0045" />
      </geometry>
    </visual>
  </link>
  <joint name="right_wrist_bead_b_in" type="revolute">
    <origin xyz="0.0975 0.014 0.014" rpy="0 0 0" />
    <parent link="right_wrist_rod_in_link" />
    <child link="right_wrist_bead_b_in_link" />
    <axis xyz="0 0 1" />
    <limit lower="-0.1" upper="0.1" effort="0" velocity="10" />
  </joint>
  <link name="right_wrist_motor_out_link">
    <inertial>
      <origin xyz="0.000486505 -0.01489087 0.0186098" rpy="0 0 0" />
      <mass value="0.0314" />
      <inertia ixx="6.479E-06" ixy="1.603E-07" ixz="-1.488E-09" iyy="1.578E-06" iyz="4.553E-08" izz="7.359E-06" />
    </inertial>
    <visual>
      <origin xyz="0 0 0" rpy="0 0 0" />
      <geometry>
        <mesh filename="../meshes/right_wrist_motor_out_link.STL" />
      </geometry>
      <material name="">
        <color rgba="0.19 0.20 0.20 1" />
      </material>
    </visual>
    <collision>
      <origin xyz="0 -0.02 0.023" rpy="0 0 0" />
      <geometry>
        <box size="0.02 0.06 0.005" />
      </geometry>
    </collision>
  </link>
  <joint name="right_wrist_motor_out" type="revolute">
    <origin xyz="0.13 0.013 -0.0255" rpy="0 0 0" />
    <parent link="right_forearm" />
    <child link="right_wrist_motor_out_link" />
    <axis xyz="0 0 1" />
    <limit lower="-0.52" upper="0.52" effort="3.5" velocity="19.9" />
  </joint>
  <link name="right_wrist_bead_a_out_link">
    <inertial>
      <origin xyz="0. 0. 0." rpy="0 0 0" />
      <mass value="0.001" />
    </inertial>
    <visual>
      <origin xyz="0 0 0" rpy="0 0 0" />
      <geometry>
        <sphere radius="0.0045" />
      </geometry>
    </visual>
  </link>
  <joint name="right_wrist_bead_a_out" type="prismatic">
    <origin xyz="0.0016327 -0.049973 0.012" rpy="0 0 0" />
    <parent link="right_wrist_motor_out_link" />
    <child link="right_wrist_bead_a_out_link" />
    <axis xyz="0 0 1" />
    <limit lower="-0.001" upper="0.001" effort="0" velocity="10" />
  </joint>
  <link name="right_wrist_rod_out_link">
    <inertial>
      <origin xyz="0.0517 0.0029 -0.0118" rpy="0 0 0" />
      <mass value="0.00696" />
      <inertia ixx="8.43E-08" ixy="-2.464E-07" ixz="6.990E-08" iyy="1.766E-06" iyz="1.101E-08" izz="1.809E-06" />
    </inertial>
    <visual>
      <origin xyz="0 0 0" rpy="0 0 0" />
      <geometry>
        <mesh filename="../meshes/right_wrist_rod_out_link.STL" />
      </geometry>
      <material name="">
        <color rgba="0.69 0.69 0.69 1" />
      </material>
    </visual>
    <collision>
      <origin xyz="0.045 0 -0.012" rpy="0 1.5708 0" />
      <geometry>
        <cylinder radius="0.004" length="0.1" />
      </geometry>
    </collision>
  </link>
  <joint name="right_wrist_rod_out" type="revolute">
    <origin xyz="0. 0. 0.01" rpy="0 0 0" />
    <parent link="right_wrist_bead_a_out_link" />
    <child link="right_wrist_rod_out_link" />
    <axis xyz="0 0 1" />
    <limit lower="0" upper="0" effort="0" velocity="0" />
  </joint>
  <link name="right_wrist_bead_b_out_link">
    <inertial>
      <origin xyz="0. 0. 0." rpy="0 0 0" />
      <mass value="0.001" />
    </inertial>
    <visual>
      <origin xyz="0 0 0.0" rpy="0 0 0" />
      <geometry>
        <sphere radius="0.0045" />
      </geometry>
    </visual>
  </link>
  <joint name="right_wrist_bead_b_out" type="revolute">
    <origin xyz="0.0975 0.014 -0.014" rpy="0 0 0" />
    <parent link="right_wrist_rod_out_link" />
    <child link="right_wrist_bead_b_out_link" />
    <axis xyz="0 0 1" />
    <limit lower="-0.1" upper="0.1" effort="0" velocity="10" />
  </joint>
  <link name="right_wrist_cross">
    <inertial>
      <origin xyz="-0.00071977 -2.491E-09 -1.747E-08" rpy="0 0 0" />
      <mass value="0.123" />
      <inertia ixx="2.352E-05" ixy="-3.529E-11" ixz="3.683E-11" iyy="1.970E-05" iyz="1.900E-11" izz="1.098E-05" />
    </inertial>
    <visual>
      <origin xyz="0 0 0" rpy="0 0 0" />
      <geometry>
        <mesh filename="../meshes/right_wrist_cross.STL" />
      </geometry>
      <material name="">
        <color rgba="0.65 0.52 0 1" />
      </material>
    </visual>
    <collision>
      <origin xyz="0 0 0" rpy="0 0 0" />
      <geometry>
        <box size="0.015 0.03 0.025" />
      </geometry>
    </collision>
  </link>
  <joint name="right_wrist_pitch" type="revolute">
    <origin xyz="0.24 0 0.00155" rpy="3.1416 0 0" />
    <parent link="right_forearm" />
    <child link="right_wrist_cross" />
    <axis xyz="0 0 1" />
    <limit lower="0" upper="0" effort="0" velocity="0" />
  </joint>
  <link name="right_wrist">
    <inertial>
      <origin xyz="0.04092324 0.0011963 -0.00018242" rpy="0 0 0" />
      <mass value="0.396" />
      <inertia ixx="0.0002687" ixy="-1.387E-06" ixz="4.739E-07" iyy="0.0001846377" iyz="-1.138E-08" izz="0.00021488" />
    </inertial>
    <visual>
      <origin xyz="0 0 0" rpy="0 0 0" />
      <geometry>
        <mesh filename="../meshes/right_wrist.STL" />
      </geometry>
      <material name="">
        <color rgba="0.65 0.62 0.59 1" />
      </material>
    </visual>
    <collision>
      <origin xyz="0.05 0 0" rpy="0 1.5708 0" />
      <geometry>
        <cylinder radius="0.035" length="0.07" />
      </geometry>
    </collision>
  </link>
  <joint name="right_wrist_yaw" type="revolute">
    <origin xyz="0 0 0" rpy="0 0 0" />
    <parent link="right_wrist_cross" />
    <child link="right_wrist" />
    <axis xyz="0 1 0" />
    <limit lower="-1.71" upper="1.71" effort="3.5" velocity="19.9" />
  </joint>
  <link name="right_wrist_bead_c_out_link">
    <inertial>
      <origin xyz="0. 0. 0." rpy="0 0 0" />
      <mass value="0.001" />
    </inertial>
    <visual>
      <origin xyz="0 0 0.0" rpy="0 0 0" />
      <geometry>
        <sphere radius="0.0045" />
      </geometry>
    </visual>
  </link>
  <joint name="right_wrist_bead_c_out" type="fixed">
    <origin xyz="-0.011 0.0228 0.019" rpy="0 0 0" />
    <parent link="right_wrist" />
    <child link="right_wrist_bead_c_out_link" />
  </joint>
  <link name="right_wrist_bead_c_in_link">
    <inertial>
      <origin xyz="0. 0. 0." rpy="0 0 0" />
      <mass value="0.001" />
    </inertial>
    <visual>
      <origin xyz="0 0 0.0" rpy="0 0 0" />
      <geometry>
        <sphere radius="0.0045" />
      </geometry>
    </visual>
  </link>
  <joint name="right_wrist_bead_c_in" type="fixed">
    <origin xyz="-0.011 0.0228 -0.019" rpy="0 0 0" />
    <parent link="right_wrist" />
    <child link="right_wrist_bead_c_in_link" />
  </joint>
  <link name="right_gripper_base">
    <inertial>
      <origin xyz="0.0031399 0 0.03058094" rpy="0 0 0" />
      <mass value="0.1834" />
      <inertia ixx="4.476E-05" ixy="-4.851E-12" ixz="-6.837E-07" iyy="4.897E-05" iyz="-8.350E-12" izz="7.060E-05" />
    </inertial>
    <visual>
      <origin xyz="0 0 0" rpy="0 0 0" />
      <geometry>
        <mesh filename="../meshes/right_gripper_base.STL" />
      </geometry>
      <material name="">
        <color rgba="0.19 0.20 0.20 1" />
      </material>
    </visual>
    <collision>
      <origin xyz="0. 0 0.033" rpy="0 0 0" />
      <geometry>
        <cylinder radius="0.028" length="0.02" />
      </geometry>
    </collision>
  </link>
  <joint name="right_wrist_roll" type="revolute">
    <origin xyz="0.0649 0 0" rpy="1.5708 0 1.5708" />
    <parent link="right_wrist" />
    <child link="right_gripper_base" />
    <axis xyz="0 0 1" />
    <limit lower="-1.71" upper="1.71" effort="0" velocity="0" />
  </joint>
</robot>